File: Obratovalna trdnost/Vaja1/MaterialX_RT_1mm_min_fi64_5.txt
""
"Test Method","Tensile test (ROUND specimen).msm"
"Sample I. D.","MaterialX_RT_1mm_min_fi64.mss"
"Specimen Number","5"

"Time (s)","Extension (mm)","Strain (%)","Load (N)","Stress (MPa)"

0.244,0.00008,0.00083,43.50128,1.36930
0.372,0.00034,0.00340,99.97218,3.14684
0.500,0.00053,0.00530,148.26091,4.66684
0.628,0.00075,0.00754,198.84096,6.25895
0.756,0.00090,0.00902,244.42495,7.69381
0.884,0.00113,0.01130,306.36328,9.64345
1.012,0.00137,0.01368,346.75506,10.91487
1.140,0.00156,0.01560,398.44773,12.54201
1.268,0.00175,0.01753,448.55232,14.11916
1.396,0.00192,0.01924,491.56635,15.47312
1.524,0.00209,0.02095,544.65779,17.14429
1.652,0.00226,0.02264,590.41384,18.58457
1.780,0.00248,0.02478,648.26715,20.40562
1.908,0.00275,0.02745,692.44803,21.79631
2.036,0.00288,0.02877,730.91519,23.00715
2.164,0.00298,0.02977,769.25133,24.21387
2.292,0.00316,0.03160,817.76729,25.74101
2.420,0.00335,0.03348,868.70499,27.34439
2.548,0.00361,0.03608,925.46936,29.13117
2.676,0.00377,0.03768,980.06248,30.84961
2.804,0.00401,0.04005,1028.88060,32.38626
2.932,0.00422,0.04217,1076.05283,33.87111
3.060,0.00444,0.04441,1123.41721,35.36201
3.188,0.00453,0.04534,1169.13342,36.80103
3.316,0.00478,0.04776,1222.91362,38.49388
3.444,0.00506,0.05064,1272.34319,40.04978
3.572,0.00522,0.05217,1322.27973,41.62164
3.700,0.00542,0.05415,1374.12915,43.25372
3.828,0.00558,0.05584,1418.60415,44.65367
3.956,0.00577,0.05766,1460.01544,45.95718
4.084,0.00592,0.05922,1511.35931,47.57334
4.212,0.00620,0.06201,1553.64270,48.90430
4.340,0.00635,0.06351,1602.05202,50.42809
4.468,0.00651,0.06508,1651.78897,51.99367
4.596,0.00676,0.06756,1710.38742,53.83818
4.724,0.00688,0.06883,1741.19676,54.80797
4.852,0.00719,0.07194,1798.58412,56.61437
4.980,0.00740,0.07401,1835.51258,57.77677
5.108,0.00749,0.07495,1882.32385,59.25026
5.236,0.00766,0.07655,1926.59666,60.64384
5.364,0.00793,0.07927,1975.11854,62.17117
5.492,0.00822,0.08223,2019.15050,63.55717
5.620,0.00842,0.08421,2064.15347,64.97374
5.748,0.00868,0.08677,2112.22794,66.48699
5.876,0.00881,0.08813,2150.60930,67.69513
6.004,0.00904,0.09036,2194.18389,69.06673
6.132,0.00922,0.09217,2250.39986,70.83625
6.260,0.00936,0.09359,2286.76933,71.98106
6.388,0.00972,0.09717,2336.71141,73.55310
6.516,0.00984,0.09837,2374.56132,74.74451
6.644,0.01006,0.10058,2419.46009,76.15779
6.772,0.01029,0.10287,2464.83854,77.58618
6.900,0.01048,0.10479,2507.92402,78.94239
7.028,0.01068,0.10681,2548.65457,80.22447
7.156,0.01079,0.10795,2587.90843,81.46007
7.284,0.01105,0.11052,2630.40618,82.79778
7.412,0.01124,0.11243,2676.02197,84.23364
7.540,0.01142,0.11424,2720.91658,85.64679
7.668,0.01169,0.11694,2761.39858,86.92105
7.796,0.01181,0.11812,2797.30072,88.05115
7.924,0.01204,0.12036,2841.44200,89.44060
8.052,0.01225,0.12245,2893.79091,91.08839
8.180,0.01245,0.12454,2931.50668,92.27558
8.308,0.01263,0.12627,2974.79967,93.63832
8.436,0.01277,0.12766,3002.16020,94.49955
8.564,0.01301,0.13013,3051.79304,96.06185
8.692,0.01316,0.13159,3091.08963,97.29880
8.820,0.01341,0.13415,3142.53010,98.91800
8.948,0.01367,0.13667,3182.87541,100.18796
9.076,0.01386,0.13860,3217.29374,101.27135
9.204,0.01403,0.14034,3257.48857,102.53657
9.332,0.01419,0.14186,3301.69725,103.92814
9.460,0.01443,0.14434,3340.35418,105.14495
9.588,0.01467,0.14673,3378.35224,106.34102
9.716,0.01486,0.14858,3421.88587,107.71133
9.844,0.01505,0.15050,3469.45729,109.20875
9.972,0.01540,0.15395,3495.32771,110.02308
10.100,0.01555,0.15550,3539.65611,111.41841
10.228,0.01563,0.15635,3564.26928,112.19316
10.356,0.01593,0.15929,3615.87290,113.81750
10.484,0.01611,0.16113,3655.12829,115.05315
10.612,0.01633,0.16331,3692.54370,116.23088
10.740,0.01656,0.16562,3733.54608,117.52152
10.868,0.01675,0.16746,3767.49622,118.59018
10.996,0.01697,0.16967,3805.87585,119.79826
11.124,0.01718,0.17176,3845.25157,121.03770
11.252,0.01741,0.17410,3872.46205,121.89420
11.380,0.01756,0.17564,3911.97217,123.13787
11.508,0.01780,0.17802,3947.77980,124.26500
11.636,0.01801,0.18013,3988.60377,125.55002
11.764,0.01825,0.18254,4026.49396,126.74270
11.892,0.01845,0.18449,4058.28743,127.74346
12.020,0.01866,0.18664,4090.74904,128.76526
12.148,0.01883,0.18827,4119.52437,129.67103
12.276,0.01902,0.19016,4158.07575,130.88452
12.404,0.01932,0.19318,4189.84511,131.88453
12.532,0.01957,0.19571,4227.67787,133.07540
12.660,0.01979,0.19785,4258.10596,134.03319
12.788,0.02001,0.20012,4289.07293,135.00794
12.916,0.02017,0.20172,4320.90135,136.00981
13.044,0.02046,0.20458,4350.03381,136.92682
13.172,0.02057,0.20573,4380.10310,137.87332
13.300,0.02092,0.20921,4410.42676,138.82782
13.428,0.02101,0.21012,4441.65143,139.81068
13.556,0.02130,0.21299,4481.91415,141.07804
13.684,0.02153,0.21534,4505.13148,141.80886
13.812,0.02173,0.21734,4533.43228,142.69969
13.940,0.02196,0.21959,4556.60763,143.42918
14.068,0.02216,0.22162,4587.94868,144.41571
14.196,0.02235,0.22347,4611.26673,145.14970
14.324,0.02258,0.22576,4645.43687,146.22528
14.452,0.02279,0.22786,4664.19843,146.81584
14.580,0.02305,0.23052,4689.45586,147.61087
14.708,0.02329,0.23289,4719.68832,148.56250
14.836,0.02353,0.23532,4743.78819,149.32110
14.964,0.02381,0.23808,4761.26270,149.87115
15.092,0.02397,0.23974,4793.23236,150.87746
15.220,0.02421,0.24208,4813.91000,151.52834
15.348,0.02454,0.24544,4842.80401,152.43784
15.476,0.02468,0.24679,4859.26167,152.95588
15.604,0.02492,0.24920,4883.97374,153.73375
15.732,0.02521,0.25211,4899.96901,154.23723
15.860,0.02538,0.25383,4935.61660,155.35932
15.988,0.02568,0.25678,4952.78023,155.89958
16.116,0.02587,0.25873,4968.08175,156.38123
16.244,0.02612,0.26124,4988.81835,157.03396
16.372,0.02652,0.26521,5014.26689,157.83501
16.500,0.02669,0.26693,5026.21178,158.21100
16.628,0.02704,0.27037,5056.12520,159.15259
16.756,0.02722,0.27222,5064.45049,159.41465
16.884,0.02752,0.27516,5092.11727,160.28552
17.012,0.02776,0.27762,5102.85239,160.62343
17.140,0.02808,0.28082,5125.61536,161.33994
17.268,0.02823,0.28230,5136.87770,161.69445
17.396,0.02842,0.28423,5157.18515,162.33367
17.524,0.02878,0.28782,5175.50333,162.91028
17.652,0.02905,0.29052,5194.11118,163.49600
17.780,0.02930,0.29298,5208.18002,163.93885
17.908,0.02959,0.29594,5227.79625,164.55631
18.036,0.02994,0.29936,5243.13669,165.03918
18.164,0.03013,0.30128,5256.09484,165.44707
18.292,0.03040,0.30395,5265.15726,165.73233
18.420,0.03060,0.30602,5279.89423,166.19621
18.548,0.03086,0.30856,5294.02098,166.64088
18.676,0.03116,0.31162,5311.99913,167.20678
18.804,0.03140,0.31396,5323.33995,167.56376
18.932,0.03163,0.31632,5339.55209,168.07407
19.060,0.03186,0.31856,5351.72986,168.45739
19.188,0.03215,0.32150,5354.88223,168.55662
19.316,0.03242,0.32417,5380.56280,169.36497
19.444,0.03263,0.32630,5400.19438,169.98292
19.572,0.03296,0.32960,5402.53573,170.05662
19.700,0.03309,0.33092,5411.20919,170.32963
19.828,0.03332,0.33315,5419.33199,170.58532
19.956,0.03362,0.33621,5439.92572,171.23355
20.084,0.03382,0.33816,5453.52063,171.66148
20.212,0.03415,0.34145,5467.44304,172.09972
20.340,0.03444,0.34436,5483.39922,172.60197
20.468,0.03465,0.34650,5490.37828,172.82165
20.596,0.03490,0.34902,5509.30943,173.41755
20.724,0.03521,0.35208,5508.22901,173.38354
20.852,0.03535,0.35348,5524.85150,173.90677
20.980,0.03558,0.35578,5532.07681,174.13421
21.108,0.03588,0.35885,5540.58961,174.40216
21.236,0.03609,0.36091,5563.46787,175.12231
21.364,0.03635,0.36352,5568.41257,175.27795
21.492,0.03656,0.36563,5583.27125,175.74566
21.620,0.03679,0.36792,5582.56282,175.72336
21.748,0.03701,0.37008,5600.97157,176.30282
21.876,0.03730,0.37295,5612.87953,176.67765
22.004,0.03756,0.37565,5621.87189,176.96070
22.132,0.03787,0.37865,5645.83749,177.71507
22.260,0.03811,0.38108,5641.97808,177.59359
22.388,0.03845,0.38451,5667.13981,178.38561
22.516,0.03872,0.38723,5672.09376,178.54154
22.644,0.03900,0.38996,5681.98426,178.85287
22.772,0.03925,0.39249,5689.43076,179.08726
22.900,0.03956,0.39558,5698.63059,179.37685
23.028,0.03975,0.39747,5714.08533,179.86332
23.156,0.04007,0.40071,5724.08449,180.17807
23.284,0.04027,0.40272,5733.69868,180.48069
23.412,0.04049,0.40494,5745.14666,180.84104
23.540,0.04080,0.40803,5754.41522,181.13279
23.668,0.04100,0.41004,5763.86602,181.43028
23.796,0.04130,0.41304,5772.95388,181.71634
23.924,0.04151,0.41512,5785.28262,182.10441
24.052,0.04181,0.41812,5794.08373,182.38145
24.180,0.04199,0.41994,5806.95075,182.78646
24.308,0.04234,0.42337,5830.46251,183.52655
24.436,0.04259,0.42592,5824.64236,183.34335
24.564,0.04286,0.42856,5840.61702,183.84618
24.692,0.04312,0.43123,5850.10998,184.14499
24.820,0.04336,0.43356,5864.92763,184.61141
24.948,0.04366,0.43661,5871.16178,184.80765
25.076,0.04392,0.43921,5884.25220,185.21970
25.204,0.04424,0.44235,5888.36064,185.34902
25.332,0.04453,0.44533,5903.33539,185.82038
25.460,0.04486,0.44861,5911.50857,186.07765
25.588,0.04514,0.45141,5922.31212,186.41771
25.716,0.04536,0.45355,5927.39580,186.57773
25.844,0.04561,0.45611,5943.31711,187.07889
25.972,0.04595,0.45950,5947.07014,187.19703
26.100,0.04618,0.46179,5969.31654,187.89728
26.228,0.04654,0.46545,5971.37298,187.96201
26.356,0.04678,0.46782,5983.81912,188.35378
26.484,0.04708,0.47083,5993.49415,188.65832
26.612,0.04741,0.47406,6007.47089,189.09827
26.740,0.04768,0.47683,6014.37170,189.31549
26.868,0.04799,0.47992,6021.28519,189.53311
26.996,0.04829,0.48287,6033.35752,189.91311
27.124,0.04856,0.48564,6043.41789,190.22978
27.252,0.04884,0.48839,6047.22063,190.34948
27.380,0.04919,0.49194,6063.14672,190.85079
27.508,0.04938,0.49378,6069.99649,191.06640
27.636,0.04964,0.49639,6086.48971,191.58556
27.764,0.04993,0.49932,6087.72218,191.62436
27.892,0.05029,0.50289,6098.77929,191.97240
28.020,0.05052,0.50524,6104.06925,192.13892
28.148,0.05076,0.50763,6112.31612,192.39851
28.276,0.05109,0.51089,6128.60172,192.91113
28.404,0.05137,0.51367,6140.17023,193.27527
28.532,0.05168,0.51679,6146.09376,193.46173
28.660,0.05194,0.51936,6153.68205,193.70059
28.788,0.05228,0.52279,6162.14046,193.96684
28.916,0.05261,0.52615,6175.35223,194.38271
29.044,0.05285,0.52851,6183.91618,194.65227
29.172,0.05316,0.53161,6192.42391,194.92007
29.300,0.05347,0.53466,6208.96316,195.44068
29.428,0.05373,0.53730,6210.47817,195.48837
29.556,0.05401,0.54011,6228.95153,196.06986
29.684,0.05425,0.54251,6226.50085,195.99272
29.812,0.05458,0.54575,6244.81424,196.56917
29.940,0.05490,0.54904,6249.48185,196.71610
30.068,0.05522,0.55215,6264.21082,197.17972
30.196,0.05550,0.55500,6278.71129,197.63616
30.324,0.05586,0.55865,6286.37560,197.87741
30.452,0.05618,0.56181,6294.54235,198.13447
30.580,0.05642,0.56419,6300.06202,198.30822
30.708,0.05675,0.56747,6309.40101,198.60218
30.836,0.05697,0.56971,6310.72125,198.64374
30.964,0.05725,0.57252,6324.42448,199.07508
31.092,0.05770,0.57702,6345.31994,199.73281
31.220,0.05792,0.57916,6343.57302,199.67782
31.348,0.05822,0.58224,6357.23404,200.10783
31.476,0.05851,0.58506,6356.11054,200.07247
31.604,0.05871,0.58705,6369.85871,200.50522
31.732,0.05905,0.59050,6379.18756,200.79887
31.860,0.05938,0.59382,6393.14183,201.23811
31.988,0.05966,0.59660,6400.51790,201.47029
32.116,0.05991,0.59914,6406.84234,201.66936
32.244,0.06027,0.60270,6419.19890,202.05831
32.372,0.06052,0.60522,6427.30042,202.31332
32.500,0.06079,0.60793,6433.18637,202.49860
32.628,0.06108,0.61075,6442.62821,202.79580
32.756,0.06141,0.61415,6455.74273,203.20861
32.884,0.06163,0.61629,6462.14175,203.41003
33.012,0.06204,0.62038,6471.67065,203.70997
33.140,0.06222,0.62223,6478.49881,203.92491
33.268,0.06252,0.62523,6477.48470,203.89298
33.396,0.06292,0.62923,6497.55325,204.52469
33.524,0.06324,0.63238,6515.17140,205.07926
33.652,0.06365,0.63651,6516.18548,205.11118
33.780,0.06387,0.63872,6527.84501,205.47819
33.908,0.06413,0.64133,6536.17953,205.74053
34.036,0.06449,0.64487,6542.44750,205.93783
34.164,0.06481,0.64810,6550.91104,206.20424
34.292,0.06508,0.65085,6560.94492,206.52008
34.420,0.06534,0.65341,6564.82620,206.64225
34.548,0.06563,0.65631,6572.48727,206.88340
34.676,0.06585,0.65853,6580.73699,207.14308
34.804,0.06620,0.66202,6584.21045,207.25241
34.932,0.06645,0.66445,6588.56672,207.38953
35.060,0.06670,0.66701,6601.65926,207.80165
35.188,0.06705,0.67051,6609.55759,208.05027
35.316,0.06729,0.67294,6625.81928,208.56214
35.444,0.06764,0.67645,6634.98042,208.85051
35.572,0.06783,0.67828,6638.23769,208.95304
35.700,0.06813,0.68130,6648.47837,209.27538
35.828,0.06847,0.68470,6654.11321,209.45275
35.956,0.06868,0.68680,6661.82874,209.69562
36.084,0.06904,0.69043,6675.80407,210.13552
36.212,0.06925,0.69250,6683.56748,210.37989
36.340,0.06947,0.69471,6690.85696,210.60934
36.468,0.06985,0.69854,6698.03683,210.83534
36.596,0.07012,0.70123,6705.91379,211.08329
36.724,0.07047,0.70469,6712.62281,211.29447
36.852,0.07061,0.70613,6728.16642,211.78374
36.980,0.07095,0.70952,6732.09615,211.90744
37.108,0.07124,0.71240,6747.16112,212.38164
37.236,0.07159,0.71593,6752.88638,212.56185
37.364,0.07185,0.71851,6756.58099,212.67815
37.492,0.07217,0.72165,6767.25894,213.01426
37.620,0.07241,0.72408,6778.95994,213.38258
37.748,0.07268,0.72680,6782.56228,213.49597
37.876,0.07304,0.73035,6794.12473,213.85992
38.004,0.07318,0.73178,6794.55075,213.87333
38.132,0.07357,0.73569,6805.41002,214.21515
38.260,0.07383,0.73829,6811.00771,214.39135
38.388,0.07402,0.74025,6825.86768,214.85910
38.516,0.07441,0.74407,6835.98315,215.17751
38.644,0.07460,0.74604,6838.82283,215.26689
38.772,0.07495,0.74949,6850.35556,215.62991
38.900,0.07525,0.75247,6856.32475,215.81780
39.028,0.07550,0.75496,6865.45233,216.10511
39.156,0.07579,0.75791,6865.15270,216.09568
39.284,0.07612,0.76122,6879.03465,216.53265
39.412,0.07637,0.76365,6883.74590,216.68094
39.540,0.07658,0.76575,6887.54096,216.80040
39.668,0.07692,0.76915,6905.93831,217.37950
39.796,0.07728,0.77277,6916.86177,217.72334
39.924,0.07751,0.77508,6922.79207,217.91001
40.052,0.07783,0.77827,6925.73552,218.00266
40.180,0.07802,0.78024,6937.46100,218.37174
40.308,0.07832,0.78322,6948.65513,218.72410
40.436,0.07862,0.78624,6947.37149,218.68370
40.564,0.07884,0.78845,6953.55091,218.87821
40.692,0.07904,0.79043,6953.51086,218.87695
40.820,0.07939,0.79394,6962.93302,219.17353
40.948,0.07956,0.79563,6973.89378,219.51854
41.076,0.07983,0.79835,6988.19004,219.96855
41.204,0.08021,0.80212,6996.91095,220.24306
41.332,0.08043,0.80425,7007.84306,220.58717
41.460,0.08077,0.80768,7013.51569,220.76573
41.588,0.08106,0.81062,7017.41868,220.88859
41.716,0.08127,0.81274,7008.00418,220.59224
41.844,0.08166,0.81656,7024.97384,221.12640
41.972,0.08179,0.81793,7024.99311,221.12701
42.100,0.08215,0.82148,7046.71958,221.81090
42.228,0.08250,0.82497,7058.70202,222.18807
42.356,0.08265,0.82650,7052.50645,221.99305
42.484,0.08295,0.82946,7064.08913,222.35764
42.612,0.08316,0.83160,7064.42813,222.36831
42.740,0.08337,0.83372,7075.10568,222.70441
42.868,0.08371,0.83710,7090.11506,223.17686
42.996,0.08401,0.84008,7100.82274,223.51391
43.124,0.08425,0.84250,7114.42283,223.94200
43.252,0.08461,0.84606,7113.89304,223.92533
43.380,0.08481,0.84807,7119.37725,224.09796
43.508,0.08506,0.85058,7121.79494,224.17406
43.636,0.08531,0.85312,7130.69317,224.45415
43.764,0.08552,0.85524,7140.95616,224.77720
43.892,0.08596,0.85958,7151.46500,225.10799
44.020,0.08616,0.86158,7154.56867,225.20568
44.148,0.08642,0.86421,7165.02252,225.53474
44.276,0.08680,0.86796,7169.14482,225.66450
44.404,0.08703,0.87032,7178.12999,225.94733
44.532,0.08730,0.87302,7193.97231,226.44600
44.660,0.08761,0.87607,7192.49054,226.39936
44.788,0.08778,0.87781,7201.62784,226.68697
44.916,0.08809,0.88088,7207.99305,226.88733
45.044,0.08836,0.88363,7217.51196,227.18696
45.172,0.08864,0.88641,7228.88237,227.54487
45.300,0.08890,0.88895,7234.11305,227.70952
45.428,0.08926,0.89256,7239.45838,227.87777
45.556,0.08945,0.89446,7255.11730,228.37067
45.684,0.08980,0.89796,7255.66475,228.38790
45.812,0.09007,0.90074,7266.25132,228.72114
45.940,0.09038,0.90379,7263.92661,228.64796
46.068,0.09075,0.90747,7269.19997,228.81395
46.196,0.09092,0.90921,7275.58888,229.01506
46.324,0.09126,0.91258,7289.59035,229.45578
46.452,0.09155,0.91549,7295.35975,229.63739
46.580,0.09176,0.91758,7308.09463,230.03825
46.708,0.09210,0.92097,7310.91043,230.12688
46.836,0.09233,0.92333,7312.97424,230.19184
46.964,0.09257,0.92569,7327.01720,230.63388
47.092,0.09290,0.92898,7342.60937,231.12467
47.220,0.09317,0.93172,7340.37416,231.05432
47.348,0.09344,0.93437,7350.11910,231.36106
47.476,0.09382,0.93816,7349.08399,231.32848
47.604,0.09400,0.94004,7362.30901,231.74476
47.732,0.09422,0.94221,7361.72069,231.72624
47.860,0.09467,0.94674,7377.74398,232.23061
47.988,0.09489,0.94887,7388.07637,232.55585
48.116,0.09517,0.95174,7389.36030,232.59626
48.244,0.09554,0.95536,7396.77808,232.82975
48.372,0.09571,0.95715,7407.63634,233.17154
48.500,0.09599,0.95992,7406.64117,233.14021
48.628,0.09630,0.96300,7417.07634,233.46868
48.756,0.09656,0.96559,7426.46853,233.76432
48.884,0.09679,0.96788,7432.07249,233.94072
49.012,0.09720,0.97197,7435.69705,234.05481
49.140,0.09740,0.97398,7447.98103,234.44148
49.268,0.09765,0.97649,7454.97559,234.66165
49.396,0.09803,0.98027,7456.53672,234.71079
49.524,0.09817,0.98167,7470.50833,235.15057
49.652,0.09848,0.98476,7468.70584,235.09384
49.780,0.09884,0.98842,7478.33946,235.39708
49.908,0.09898,0.98980,7482.61866,235.53177
50.036,0.09927,0.99268,7488.08513,235.70384
50.164,0.09965,0.99650,7500.39288,236.09125
50.292,0.09984,0.99841,7503.74491,236.19677
50.420,0.10022,1.00220,7519.51276,236.69309
50.548,0.10068,1.00682,7528.89719,236.98849
50.676,0.10087,1.00871,7533.44559,237.13166
50.804,0.10121,1.01210,7533.52660,237.13421
50.932,0.10137,1.01371,7532.63722,237.10622
51.060,0.10159,1.01587,7550.10487,237.65605
51.188,0.10200,1.02005,7555.39763,237.82265
51.316,0.10220,1.02196,7565.70216,238.14701
51.444,0.10245,1.02448,7573.11351,238.38030
51.572,0.10281,1.02814,7579.66354,238.58647
51.700,0.10292,1.02921,7576.51242,238.48728
51.828,0.10329,1.03288,7577.32892,238.51298
51.956,0.10358,1.03577,7587.44414,238.83138
52.084,0.10373,1.03729,7597.95490,239.16223
52.212,0.10404,1.04039,7611.91994,239.60181
52.340,0.10439,1.04387,7618.46367,239.80779
52.468,0.10457,1.04573,7620.86329,239.88332
52.596,0.10493,1.04933,7629.71558,240.16197
52.724,0.10516,1.05162,7636.89279,240.38789
52.852,0.10528,1.05275,7644.57150,240.62959
52.980,0.10580,1.05796,7651.10138,240.83513
53.108,0.10599,1.05995,7662.40974,241.19109
53.236,0.10623,1.06233,7662.27102,241.18672
53.364,0.10660,1.06598,7674.45418,241.57021
53.492,0.10671,1.06715,7679.45706,241.72769
53.620,0.10706,1.07061,7686.82387,241.95958
53.748,0.10739,1.07391,7697.01183,242.28027
53.876,0.10762,1.07623,7705.50940,242.54775
54.004,0.10792,1.07924,7706.41853,242.57636
54.132,0.10822,1.08220,7711.63916,242.74069
54.260,0.10845,1.08451,7726.15419,243.19759
54.388,0.10880,1.08801,7724.14651,243.13439
54.516,0.10915,1.09149,7732.86494,243.40882
54.644,0.10926,1.09261,7734.05822,243.44638
54.772,0.10970,1.09699,7741.49584,243.68050
54.900,0.10995,1.09950,7749.92430,243.94580
55.028,0.11015,1.10150,7751.48888,243.99505
55.156,0.11051,1.10513,7765.00870,244.42062
55.284,0.11066,1.10663,7767.93942,244.51287
55.412,0.11101,1.11010,7780.58802,244.91101
55.540,0.11135,1.11350,7784.02150,245.01909
55.668,0.11154,1.11542,7795.22789,245.37183
55.796,0.11188,1.11880,7797.95188,245.45757
55.924,0.11212,1.12117,7802.62592,245.60470
56.052,0.11237,1.12367,7806.05920,245.71277
56.180,0.11259,1.12586,7811.33358,245.87879
56.308,0.11285,1.12853,7827.23217,246.37924
56.436,0.11320,1.13203,7829.38251,246.44692
56.564,0.11358,1.13575,7834.81011,246.61777
56.692,0.11376,1.13760,7841.54888,246.82989
56.820,0.11401,1.14008,7846.72688,246.99287
56.948,0.11439,1.14389,7851.63670,247.14742
57.076,0.11465,1.14648,7872.99667,247.81977
57.204,0.11502,1.15022,7873.22242,247.82688
57.332,0.11529,1.15286,7877.09374,247.94874
57.460,0.11544,1.15439,7879.25664,248.01682
57.588,0.11587,1.15870,7885.98538,248.22862
57.716,0.11609,1.16095,7890.04811,248.35650
57.844,0.11620,1.16204,7904.77359,248.82002
57.972,0.11663,1.16625,7905.11309,248.83071
58.100,0.11697,1.16971,7916.85015,249.20016
58.228,0.11711,1.17110,7921.22242,249.33778
58.356,0.11755,1.17546,7926.66710,249.50917
58.484,0.11771,1.17712,7930.46611,249.62875
58.612,0.11801,1.18012,7943.39569,250.03574
58.740,0.11856,1.18562,7944.85925,250.08180
58.868,0.11873,1.18727,7955.29304,250.41023
58.996,0.11907,1.19074,7954.78763,250.39432
59.124,0.11942,1.19420,7958.84703,250.52210
59.252,0.11958,1.19581,7973.06310,250.96958
59.380,0.11991,1.19910,7977.77821,251.11800
59.508,0.12018,1.20176,7987.81332,251.43388
59.636,0.12041,1.20411,7992.75579,251.58945
59.764,0.12073,1.20730,7988.32193,251.44989
59.892,0.12098,1.20985,7991.64066,251.55435
60.020,0.12119,1.21185,8003.22339,251.91894
60.148,0.12150,1.21502,8016.02773,252.32199
60.276,0.12182,1.21816,8023.67079,252.56257
60.404,0.12198,1.21980,8015.13341,252.29384
60.532,0.12238,1.22385,8034.37206,252.89942
60.660,0.12267,1.22666,8041.54615,253.12524
60.788,0.12289,1.22893,8041.80465,253.13337
60.916,0.12324,1.23245,8052.57030,253.47225
61.044,0.12349,1.23489,8049.68195,253.38133
61.172,0.12370,1.23702,8052.16610,253.45952
61.300,0.12399,1.23993,8060.15128,253.71087
61.428,0.12425,1.24254,8063.67636,253.82183
61.556,0.12450,1.24503,8082.10589,254.40194
61.684,0.12474,1.24740,8085.65647,254.51371
61.812,0.12513,1.25126,8103.34954,255.07063
61.940,0.12526,1.25259,8101.48569,255.01196
62.068,0.12568,1.25683,8116.10743,255.47222
62.196,0.12583,1.25831,8109.62189,255.26807
62.324,0.12607,1.26069,8111.45564,255.32579
62.452,0.12640,1.26403,8110.33253,255.29044
62.580,0.12647,1.26468,8115.84873,255.46407
62.708,0.12678,1.26784,8128.78441,255.87125
62.836,0.12716,1.27159,8151.72246,256.59328
62.964,0.12741,1.27412,8149.93718,256.53708
63.092,0.12766,1.27663,8154.77339,256.68931
63.220,0.12801,1.28015,8154.62806,256.68474
63.348,0.12818,1.28179,8173.13720,257.26735
63.476,0.12846,1.28463,8175.36493,257.33747
63.604,0.12874,1.28744,8183.56002,257.59543
63.732,0.12902,1.29021,8186.40143,257.68487
63.860,0.12942,1.29415,8194.48414,257.93929
63.988,0.12958,1.29577,8200.81904,258.13870
64.116,0.12985,1.29852,8207.42244,258.34655
64.244,0.13020,1.30201,8209.89202,258.42429
64.372,0.13040,1.30396,8223.49296,258.85241
64.500,0.13079,1.30790,8225.93762,258.92936
64.628,0.13104,1.31037,8235.60787,259.23375
64.756,0.13132,1.31323,8230.88154,259.08498
64.884,0.13167,1.31667,8236.55424,259.26354
65.012,0.13176,1.31761,8242.53897,259.45192
65.140,0.13211,1.32109,8246.09130,259.56374
65.268,0.13246,1.32462,8259.49126,259.98553
65.396,0.13271,1.32709,8264.92070,260.15644
65.524,0.13292,1.32916,8265.13259,260.16311
65.652,0.13326,1.33263,8271.27202,260.35636
65.780,0.13354,1.33540,8280.25635,260.63916
65.908,0.13377,1.33766,8280.83662,260.65743
66.036,0.13407,1.34072,8283.58743,260.74401
66.164,0.13431,1.34309,8289.18490,260.92021
66.292,0.13455,1.34547,8290.12404,260.94977
66.420,0.13485,1.34849,8298.12030,261.20147
66.548,0.13508,1.35082,8306.49769,261.46517
66.676,0.13529,1.35289,8311.63855,261.62698
66.804,0.13565,1.35653,8323.51071,262.00069
66.932,0.13593,1.35927,8321.17377,261.92713
67.060,0.13611,1.36106,8337.42781,262.43876
67.188,0.13654,1.36542,8338.86979,262.48415
67.316,0.13685,1.36847,8344.91673,262.67449
67.444,0.13696,1.36957,8338.41415,262.46981
67.572,0.13741,1.37412,8351.79645,262.89104
67.700,0.13761,1.37612,8356.71088,263.04573
67.828,0.13788,1.37880,8367.81628,263.39530
67.956,0.13824,1.38240,8373.36064,263.56982
68.084,0.13844,1.38440,8376.07410,263.65523
68.212,0.13874,1.38737,8381.52389,263.82678
68.340,0.13904,1.39035,8395.29176,264.26015
68.468,0.13920,1.39200,8395.45696,264.26535
68.596,0.13963,1.39628,8411.57729,264.77277
68.724,0.13991,1.39911,8414.39907,264.86160
68.852,0.14013,1.40133,8420.79616,265.06296
68.980,0.14039,1.40393,8417.37054,264.95513
69.108,0.14078,1.40783,8424.31516,265.17373
69.236,0.14098,1.40985,8427.27519,265.26690
69.364,0.14132,1.41320,8434.58382,265.49696
69.492,0.14151,1.41514,8441.39923,265.71149
69.620,0.14183,1.41832,8446.61599,265.87569
69.748,0.14215,1.42150,8458.09248,266.23694
69.876,0.14251,1.42509,8462.47494,266.37489
70.004,0.14270,1.42705,8463.79260,266.41637
70.132,0.14297,1.42969,8470.14960,266.61647
70.260,0.14327,1.43268,8471.74573,266.66671
70.388,0.14357,1.43568,8485.89981,267.11224
70.516,0.14386,1.43861,8486.34017,267.12610
70.644,0.14420,1.44198,8486.03470,267.11648
70.772,0.14439,1.44389,8494.80931,267.39268
70.900,0.14468,1.44683,8499.20142,267.53094
71.028,0.14496,1.44957,8510.14542,267.87542
71.156,0.14520,1.45205,8507.59859,267.79526
71.284,0.14552,1.45519,8519.00923,268.15443
71.412,0.14579,1.45795,8521.11414,268.22069
71.540,0.14602,1.46018,8527.94500,268.43570
71.668,0.14633,1.46327,8541.15776,268.85160
71.796,0.14665,1.46648,8546.92451,269.03312
71.924,0.14682,1.46817,8547.91392,269.06427
72.052,0.14720,1.47203,8555.55836,269.30489
72.180,0.14760,1.47600,8557.88937,269.37827
72.308,0.14782,1.47824,8571.01806,269.79152
72.436,0.14810,1.48103,8572.67915,269.84381
72.564,0.14836,1.48361,8579.60588,270.06184
72.692,0.14863,1.48628,8578.98495,270.04230
72.820,0.14890,1.48903,8589.71941,270.38019
72.948,0.14917,1.49172,8594.47140,270.52977
73.076,0.14948,1.49480,8601.48751,270.75061
73.204,0.14971,1.49713,8602.09997,270.76989
73.332,0.15001,1.50013,8607.63554,270.94414
73.460,0.15025,1.50249,8610.15455,271.02343
73.588,0.15054,1.50543,8616.67391,271.22864
73.716,0.15088,1.50881,8622.68685,271.41791
73.844,0.15111,1.51106,8630.13676,271.65241
73.972,0.15145,1.51453,8633.70158,271.76462
74.100,0.15166,1.51663,8640.49312,271.97840
74.228,0.15193,1.51926,8634.76988,271.79825
74.356,0.15224,1.52243,8656.70626,272.48874
74.484,0.15255,1.52548,8656.55534,272.48399
74.612,0.15284,1.52836,8664.52337,272.73481
74.740,0.15306,1.53061,8668.39049,272.85653
74.868,0.15335,1.53355,8676.12095,273.09986
74.996,0.15363,1.53635,8676.30318,273.10560
75.124,0.15392,1.53924,8686.28484,273.41980
75.252,0.15418,1.54181,8687.34554,273.45318
75.380,0.15452,1.54524,8694.78783,273.68745
75.508,0.15477,1.54769,8696.50279,273.74143
75.636,0.15514,1.55135,8702.47615,273.92945
75.764,0.15554,1.55537,8701.83394,273.90924
75.892,0.15569,1.55689,8711.52352,274.21424
76.020,0.15606,1.56058,8715.24818,274.33148
76.148,0.15626,1.56259,8729.85456,274.79125
76.276,0.15663,1.56633,8727.91273,274.73012
76.404,0.15685,1.56846,8734.26839,274.93018
76.532,0.15713,1.57127,8741.93360,275.17146
76.660,0.15743,1.57435,8749.21778,275.40075
76.788,0.15768,1.57681,8753.71357,275.54226
76.916,0.15791,1.57907,8757.10942,275.64915
77.044,0.15825,1.58249,8763.45093,275.84877
77.172,0.15860,1.58595,8771.69768,276.10835
77.300,0.15872,1.58719,8769.66946,276.04451
77.428,0.15912,1.59117,8775.67337,276.23349
77.556,0.15944,1.59439,8784.48243,276.51078
77.684,0.15958,1.59575,8791.33424,276.72645
77.812,0.15998,1.59984,8801.51748,277.04699
77.940,0.16022,1.60224,8795.86944,276.86921
78.068,0.16053,1.60533,8804.99445,277.15644
78.196,0.16074,1.60744,8805.03842,277.15782
78.324,0.16105,1.61048,8807.54250,277.23665
78.452,0.16133,1.61331,8811.25823,277.35361
78.580,0.16158,1.61579,8818.22686,277.57296
78.708,0.16192,1.61917,8821.41484,277.67331
78.836,0.16214,1.62140,8836.37011,278.14406
78.964,0.16243,1.62435,8830.78762,277.96834
79.092,0.16268,1.62675,8839.76986,278.25107
79.220,0.16293,1.62934,8837.17193,278.16930
79.348,0.16316,1.63158,8853.60776,278.68665
79.476,0.16348,1.63477,8855.29018,278.73961
79.604,0.16382,1.63817,8868.58086,279.15796
79.732,0.16406,1.64064,8870.06225,279.20459
79.860,0.16434,1.64345,8873.45704,279.31145
79.988,0.16470,1.64700,8880.96314,279.54772
80.116,0.16487,1.64870,8881.47294,279.56377
80.244,0.16517,1.65167,8884.76901,279.66752
80.372,0.16544,1.65436,8889.86378,279.82789
80.500,0.16576,1.65762,8893.61084,279.94583
80.628,0.16603,1.66027,8901.48595,280.19372
80.756,0.16629,1.66293,8894.03666,279.95924
80.884,0.16660,1.66599,8911.36679,280.50474
81.012,0.16683,1.66833,8921.40126,280.82060
81.140,0.16718,1.67175,8930.38626,281.10342
81.268,0.16752,1.67516,8935.72014,281.27132
81.396,0.16772,1.67719,8929.85994,281.08685
81.524,0.16800,1.68000,8941.70209,281.45961
81.652,0.16826,1.68264,8938.47912,281.35816
81.780,0.16856,1.68560,8947.91225,281.65509
81.908,0.16879,1.68785,8955.73508,281.90133
82.036,0.16910,1.69102,8959.55596,282.02160
82.164,0.16941,1.69414,8955.63366,281.89814
82.292,0.16962,1.69618,8954.40687,281.85952
82.420,0.16987,1.69872,8964.78743,282.18627
82.548,0.17020,1.70199,8967.26597,282.26429
82.676,0.17050,1.70500,8969.93896,282.34843
82.804,0.17068,1.70680,8984.06987,282.79323
82.932,0.17105,1.71052,8985.58196,282.84083
83.060,0.17127,1.71265,8999.76705,283.28733
83.188,0.17154,1.71541,8993.60893,283.09349
83.316,0.17178,1.71781,8996.19819,283.17500
83.444,0.17202,1.72024,8999.35211,283.27427
83.572,0.17223,1.72230,9009.52681,283.59454
83.700,0.17254,1.72538,9012.29052,283.68154
83.828,0.17288,1.72875,9028.01596,284.17653
83.956,0.17314,1.73138,9028.42271,284.18933
84.084,0.17343,1.73429,9037.24745,284.46711
84.212,0.17384,1.73839,9040.77341,284.57810
84.340,0.17403,1.74027,9050.00106,284.86856
84.468,0.17432,1.74320,9047.79440,284.79910
84.596,0.17473,1.74731,9072.58757,285.57952
84.724,0.17497,1.74975,9061.94463,285.24451
84.852,0.17539,1.75387,9073.04026,285.59377
84.980,0.17554,1.75545,9067.52110,285.42004
85.108,0.17575,1.75751,9073.61074,285.61172
85.236,0.17607,1.76066,9080.84479,285.83943
85.364,0.17646,1.76462,9085.42918,285.98374
85.492,0.17668,1.76684,9086.96637,286.03212
85.620,0.17698,1.76982,9091.92652,286.18825
85.748,0.17730,1.77304,9094.13793,286.25786
85.876,0.17755,1.77548,9097.98558,286.37898
86.004,0.17783,1.77828,9105.32530,286.61001
86.132,0.17802,1.78016,9116.47689,286.96103
86.260,0.17834,1.78337,9116.45447,286.96032
86.388,0.17862,1.78616,9119.06832,287.04260
86.516,0.17885,1.78846,9111.08382,286.79127
86.644,0.17918,1.79179,9123.10764,287.16975
86.772,0.17943,1.79433,9140.31130,287.71127
86.900,0.17979,1.79788,9139.14598,287.67459
87.028,0.18008,1.80082,9142.62253,287.78402
87.156,0.18032,1.80318,9148.95790,287.98344
87.284,0.18060,1.80601,9150.75153,288.03990
87.412,0.18095,1.80954,9152.49504,288.09478
87.540,0.18124,1.81241,9160.24576,288.33875
87.668,0.18143,1.81428,9170.64805,288.66619
87.796,0.18185,1.81850,9169.82531,288.64029
87.924,0.18206,1.82064,9176.31527,288.84457
88.052,0.18235,1.82351,9184.78168,289.11107
88.180,0.18272,1.82716,9186.83832,289.17581
88.308,0.18294,1.82939,9192.22067,289.34523
88.436,0.18318,1.83182,9194.57116,289.41922
88.564,0.18345,1.83446,9198.56994,289.54509
88.692,0.18379,1.83792,9198.66249,289.54800
88.820,0.18406,1.84060,9206.01030,289.77929
88.948,0.18437,1.84371,9202.54986,289.67036
89.076,0.18462,1.84620,9208.48289,289.85712
89.204,0.18489,1.84886,9219.66642,290.20915
89.332,0.18525,1.85253,9226.71388,290.43098
89.460,0.18551,1.85509,9230.90280,290.56284
89.588,0.18577,1.85770,9233.88011,290.65655
89.716,0.18610,1.86103,9230.46271,290.54898
89.844,0.18640,1.86396,9241.83837,290.90706
89.972,0.18663,1.86627,9237.94653,290.78455
90.100,0.18686,1.86859,9245.77696,291.03103
90.228,0.18712,1.87123,9241.29399,290.88992
90.356,0.18740,1.87404,9254.72084,291.31256
90.484,0.18769,1.87686,9262.10932,291.54513
90.612,0.18796,1.87960,9265.37267,291.64785
90.740,0.18818,1.88177,9272.55656,291.87398
90.868,0.18854,1.88538,9277.74340,292.03725
90.996,0.18877,1.88767,9271.46338,291.83957
91.124,0.18901,1.89012,9279.02085,292.07746
91.252,0.18936,1.89360,9284.86642,292.26146
91.380,0.18971,1.89706,9295.74951,292.60403
91.508,0.18995,1.89954,9296.88484,292.63976
91.636,0.19017,1.90168,9299.37878,292.71827
91.764,0.19039,1.90388,9311.01275,293.08447
91.892,0.19082,1.90816,9320.51274,293.38350
92.020,0.19106,1.91055,9316.45399,293.25575
92.148,0.19137,1.91368,9317.69240,293.29473
92.276,0.19159,1.91594,9318.12109,293.30822
92.404,0.19200,1.91996,9325.40566,293.53752
92.532,0.19228,1.92278,9328.43866,293.63299
92.660,0.19258,1.92582,9337.15737,293.90743
92.788,0.19286,1.92858,9349.12706,294.28420
92.916,0.19316,1.93163,9351.33055,294.35356
93.044,0.19342,1.93425,9344.13175,294.12696
93.172,0.19370,1.93705,9359.15372,294.59981
93.300,0.19406,1.94061,9359.71818,294.61758
93.428,0.19432,1.94317,9359.77480,294.61936
93.556,0.19464,1.94636,9377.44810,295.17567
93.684,0.19490,1.94900,9367.68599,294.86839
93.812,0.19510,1.95099,9368.80868,294.90372
93.940,0.19547,1.95469,9378.35078,295.20408
94.068,0.19568,1.95680,9380.89479,295.28416
94.196,0.19603,1.96027,9388.03939,295.50905
94.324,0.19632,1.96317,9397.02552,295.79191
94.452,0.19656,1.96562,9393.51385,295.68137
94.580,0.19686,1.96857,9396.66309,295.78050
94.708,0.19716,1.97160,9402.63388,295.96845
94.836,0.19738,1.97382,9408.02249,296.13806
94.964,0.19768,1.97679,9411.94798,296.26163
95.092,0.19797,1.97969,9422.50623,296.59397
95.220,0.19824,1.98245,9412.09986,296.26641
95.348,0.19868,1.98684,9422.58618,296.59649
95.476,0.19896,1.98960,9429.61778,296.81782
95.604,0.19919,1.99194,9439.10934,297.11659
95.732,0.19942,1.99422,9441.33919,297.18678
95.860,0.19971,1.99713,9442.12892,297.21164
95.988,0.20000,2.00001,9447.11536,297.36860
96.116,0.20032,2.00325,9451.50421,297.50675
96.244,0.20064,2.00643,9462.50706,297.85309
96.372,0.20087,2.00871,9463.35741,297.87985
96.500,0.20112,2.01118,9465.78352,297.95622
96.628,0.20140,2.01400,9472.15740,298.15685
96.756,0.20173,2.01729,9471.76275,298.14443
96.884,0.20201,2.02012,9482.78029,298.49123
97.012,0.20225,2.02247,9476.92724,298.30699
97.140,0.20256,2.02560,9484.68138,298.55107
97.268,0.20285,2.02850,9488.15456,298.66040
97.396,0.20299,2.02990,9495.12700,298.87987
97.524,0.20343,2.03429,9502.87828,299.12386
97.652,0.20376,2.03756,9504.35374,299.17030
97.780,0.20406,2.04061,9508.24250,299.29271
97.908,0.20429,2.04295,9509.51958,299.33291
98.036,0.20463,2.04627,9513.19561,299.44862
98.164,0.20491,2.04908,9520.84775,299.68949
98.292,0.20512,2.05124,9521.66782,299.71530
98.420,0.20552,2.05518,9530.53379,299.99438
98.548,0.20573,2.05732,9532.63563,300.06054
98.676,0.20598,2.05978,9528.42380,299.92796
98.804,0.20625,2.06252,9538.81866,300.25516
98.932,0.20661,2.06609,9537.99190,300.22914
99.060,0.20685,2.06850,9548.36349,300.55560
99.188,0.20714,2.07139,9553.42275,300.71486
99.316,0.20745,2.07449,9559.98101,300.92129
99.444,0.20773,2.07727,9562.43465,300.99853
99.572,0.20804,2.08042,9566.46010,301.12523
99.700,0.20837,2.08370,9568.82494,301.19967
99.828,0.20861,2.08614,9574.43128,301.37615
99.956,0.20889,2.08887,9577.92664,301.48617
100.084,0.20928,2.09280,9586.99190,301.77152
100.212,0.20950,2.09499,9584.94604,301.70712
100.340,0.20982,2.09818,9587.39744,301.78428
100.468,0.21019,2.10187,9581.93932,301.61248
100.596,0.21051,2.10514,9594.98332,302.02307
100.724,0.21075,2.10747,9603.23779,302.28289
100.852,0.21109,2.11091,9614.51957,302.63801
100.980,0.21131,2.11310,9606.21092,302.37648
101.108,0.21163,2.11629,9610.44213,302.50967
101.236,0.21196,2.11963,9617.30218,302.72560
101.364,0.21224,2.12241,9623.20296,302.91134
101.492,0.21248,2.12482,9622.88003,302.90118
101.620,0.21276,2.12764,9621.29551,302.85130
101.748,0.21315,2.13153,9629.86060,303.12090
101.876,0.21340,2.13398,9637.04761,303.34713
102.004,0.21367,2.13668,9635.12913,303.28674
102.132,0.21404,2.14036,9652.78043,303.84236
102.260,0.21427,2.14273,9638.62195,303.39669
102.388,0.21459,2.14585,9656.49338,303.95923
102.516,0.21485,2.14855,9653.95396,303.87930
102.644,0.21519,2.15190,9661.28307,304.11000
102.772,0.21544,2.15444,9661.48232,304.11627
102.900,0.21573,2.15726,9664.27559,304.20419
103.028,0.21600,2.16002,9663.24812,304.17185
103.156,0.21624,2.16242,9664.06171,304.19746
103.284,0.21651,2.16511,9670.65041,304.40485
103.412,0.21677,2.16767,9672.31387,304.45721
103.540,0.21709,2.17089,9672.79571,304.47238
103.668,0.21729,2.17288,9680.75912,304.72305
103.796,0.21760,2.17604,9680.64212,304.71936
103.924,0.21794,2.17943,9684.85332,304.85192
104.052,0.21816,2.18156,9697.92327,305.26333
104.180,0.21838,2.18380,9690.42809,305.02740
104.308,0.21873,2.18726,9703.45864,305.43756
104.436,0.21893,2.18925,9700.92444,305.35779
104.564,0.21932,2.19315,9706.37644,305.52941
104.692,0.21951,2.19509,9710.76440,305.66753
104.820,0.21976,2.19764,9717.56631,305.88163
104.948,0.22006,2.20055,9722.53430,306.03801
105.076,0.22036,2.20359,9729.04529,306.24296
105.204,0.22061,2.20613,9733.73532,306.39059
105.332,0.22098,2.20979,9741.53687,306.63616
105.460,0.22126,2.21259,9747.07150,306.81037
105.588,0.22151,2.21511,9742.85890,306.67777
105.716,0.22183,2.21825,9740.37115,306.59947
105.844,0.22203,2.22034,9756.41067,307.10434
105.972,0.22244,2.22438,9752.49532,306.98110
106.100,0.22271,2.22712,9760.75408,307.24106
106.228,0.22300,2.22998,9754.26176,307.03670
106.356,0.22323,2.23234,9764.22714,307.35038
106.484,0.22353,2.23530,9767.64632,307.45801
106.612,0.22381,2.23815,9770.47845,307.54716
106.740,0.22399,2.23994,9769.32244,307.51077
106.868,0.22431,2.24313,9768.23337,307.47649
106.996,0.22458,2.24576,9778.42039,307.79715
107.124,0.22483,2.24830,9780.04966,307.84843
107.252,0.22504,2.25039,9788.39630,308.11116
107.380,0.22542,2.25416,9796.61885,308.36998
107.508,0.22570,2.25700,9790.31056,308.17142
107.636,0.22595,2.25955,9809.91363,308.78847
107.764,0.22627,2.26272,9810.13433,308.79541
107.892,0.22658,2.26577,9813.46866,308.90037
108.020,0.22684,2.26845,9810.81051,308.81670
108.148,0.22722,2.27218,9809.22289,308.76672
108.276,0.22742,2.27416,9822.72038,309.19159
108.404,0.22770,2.27696,9819.02501,309.07527
108.532,0.22802,2.28023,9829.21830,309.39612
108.660,0.22833,2.28327,9824.45021,309.24604
108.788,0.22857,2.28570,9825.61433,309.28268
108.916,0.22895,2.28948,9826.11078,309.29831
109.044,0.22923,2.29233,9832.80844,309.50913
109.172,0.22947,2.29470,9845.78221,309.91751
109.300,0.22977,2.29772,9845.56753,309.91075
109.428,0.22999,2.29993,9848.18272,309.99307
109.556,0.23034,2.30337,9851.30194,310.09125
109.684,0.23061,2.30608,9855.47166,310.22251
109.812,0.23090,2.30905,9863.73734,310.48269
109.940,0.23123,2.31231,9864.34027,310.50166
110.068,0.23153,2.31533,9875.34631,310.84810
110.196,0.23191,2.31910,9879.91030,310.99176
110.324,0.23217,2.32172,9876.45636,310.88304
110.452,0.23236,2.32358,9879.56366,310.98085
110.580,0.23266,2.32659,9886.11996,311.18723
110.708,0.23290,2.32903,9881.92804,311.05528
110.836,0.23329,2.33287,9895.19971,311.47303
110.964,0.23349,2.33495,9900.25230,311.63207
111.092,0.23384,2.33837,9903.61424,311.73790
111.220,0.23411,2.34111,9894.88326,311.46307
111.348,0.23436,2.34364,9907.15965,311.84950
111.476,0.23467,2.34669,9912.31603,312.01181
111.604,0.23503,2.35027,9916.06135,312.12970
111.732,0.23525,2.35253,9915.96899,312.12679
111.860,0.23562,2.35615,9919.23716,312.22966
111.988,0.23581,2.35814,9918.06306,312.19271
112.116,0.23615,2.36151,9923.66204,312.36895
112.244,0.23641,2.36405,9930.09736,312.57151
112.372,0.23677,2.36773,9930.01969,312.56907
112.500,0.23709,2.37092,9935.85670,312.75280
112.628,0.23747,2.37474,9945.36775,313.05218
112.756,0.23767,2.37667,9938.20576,312.82674
112.884,0.23795,2.37946,9941.09204,312.91759
113.012,0.23825,2.38249,9946.87731,313.09970
113.140,0.23856,2.38559,9954.34346,313.33471
113.268,0.23883,2.38835,9960.85895,313.53980
113.396,0.23905,2.39054,9955.59754,313.37419
113.524,0.23940,2.39400,9961.09421,313.54721
113.652,0.23967,2.39666,9962.01577,313.57621
113.780,0.23993,2.39934,9961.70208,313.56634
113.908,0.24021,2.40209,9954.76060,313.34784
114.036,0.24041,2.40408,9958.65525,313.47043
114.164,0.24075,2.40746,9970.67460,313.84877
114.292,0.24100,2.41003,9976.63708,314.03645
114.420,0.24139,2.41387,9983.64146,314.25693
114.548,0.24165,2.41649,9986.00627,314.33137
114.676,0.24187,2.41868,9993.96559,314.58190
114.804,0.24216,2.42161,9997.03712,314.67859
114.932,0.24252,2.42516,9995.79244,314.63941
115.060,0.24273,2.42733,9987.59778,314.38146
115.188,0.24304,2.43045,9992.33437,314.53056
115.316,0.24323,2.43235,9999.10989,314.74383
115.444,0.24353,2.43526,10000.26970,314.78034
115.572,0.24374,2.43740,10008.73412,315.04678
115.700,0.24414,2.44137,10013.36977,315.19269
115.828,0.24438,2.44378,10013.90912,315.20967
115.956,0.24468,2.44675,10023.13236,315.49999
116.084,0.24499,2.44993,10024.26470,315.53564
116.212,0.24521,2.45212,10020.16950,315.40673
116.340,0.24555,2.45553,10020.86256,315.42855
116.468,0.24587,2.45874,10019.64366,315.39018