File: Obratovalna trdnost/Vaja1/MaterialX_RT_1mm_min_fi64_4.txt
""
"Test Method","Tensile test (ROUND specimen).msm"
"Sample I. D.","MaterialX_RT_1mm_min_fi64.mss"
"Specimen Number","4"

"Time (s)","Extension (mm)","Strain (%)","Load (N)","Stress (MPa)"

0.372,0.00018,0.00179,107.45686,3.38244
0.628,0.00053,0.00534,208.37385,6.55902
0.884,0.00095,0.00955,305.78698,9.62531
1.140,0.00131,0.01306,404.68116,12.73822
1.396,0.00173,0.01735,509.66095,16.04269
1.652,0.00214,0.02143,599.83213,18.88103
1.908,0.00264,0.02639,695.87319,21.90413
2.164,0.00298,0.02984,789.92741,24.86469
2.420,0.00340,0.03396,897.93692,28.26453
2.676,0.00373,0.03728,999.40255,31.45838
2.932,0.00415,0.04147,1102.24568,34.69559
3.188,0.00459,0.04587,1201.02898,37.80501
3.444,0.00498,0.04980,1302.83646,41.00962
3.700,0.00534,0.05339,1397.42711,43.98707
3.956,0.00572,0.05717,1495.04672,47.05986
4.212,0.00615,0.06148,1593.25932,50.15132
4.468,0.00653,0.06534,1683.50741,52.99207
4.724,0.00691,0.06911,1793.57745,56.45677
4.980,0.00734,0.07340,1892.77199,59.57913
5.236,0.00777,0.07773,1984.71554,62.47326
5.492,0.00817,0.08165,2084.74996,65.62206
5.748,0.00861,0.08605,2187.96231,68.87089
6.004,0.00891,0.08906,2284.20980,71.90049
6.260,0.00929,0.09286,2374.93767,74.75635
6.516,0.00966,0.09660,2469.80704,77.74257
6.772,0.01015,0.10150,2566.02028,80.77110
7.028,0.01061,0.10613,2654.11448,83.54405
7.284,0.01083,0.10830,2737.78933,86.17790
7.540,0.01118,0.11176,2820.78574,88.79039
7.796,0.01163,0.11626,2907.45373,91.51846
8.052,0.01202,0.12021,2999.09704,94.40313
8.308,0.01243,0.12428,3091.51588,97.31222
8.564,0.01274,0.12741,3173.20887,99.88368
8.820,0.01322,0.13215,3272.59426,103.01206
9.076,0.01354,0.13541,3366.24744,105.95999
9.332,0.01396,0.13963,3452.78174,108.68385
9.588,0.01432,0.14324,3542.12760,111.49621
9.844,0.01467,0.14671,3631.58619,114.31211
10.100,0.01509,0.15091,3717.80442,117.02602
10.356,0.01538,0.15377,3806.22428,119.80923
10.612,0.01587,0.15870,3890.86796,122.47357
10.868,0.01628,0.16276,3965.29452,124.81631
11.124,0.01676,0.16763,4051.13250,127.51825
11.380,0.01714,0.17136,4125.96259,129.87369
11.636,0.01752,0.17517,4197.08136,132.11231
11.892,0.01794,0.17939,4281.11058,134.75731
12.148,0.01841,0.18411,4364.20895,137.37301
12.404,0.01887,0.18869,4430.84956,139.47067
12.660,0.01933,0.19333,4499.86624,141.64312
12.916,0.01972,0.19720,4573.47377,143.96008
13.172,0.02024,0.20236,4636.52326,145.94470
13.428,0.02073,0.20733,4697.86135,147.87545
13.684,0.02132,0.21323,4756.91452,149.73428
13.940,0.02183,0.21834,4802.18186,151.15917
14.196,0.02228,0.22280,4861.68939,153.03230
14.452,0.02285,0.22852,4896.42699,154.12574
14.708,0.02336,0.23363,4948.53734,155.76603
14.964,0.02394,0.23945,4994.73448,157.22018
15.220,0.02442,0.24424,5025.41129,158.18580
15.476,0.02495,0.24954,5059.96414,159.27343
15.732,0.02547,0.25475,5084.98120,160.06089
15.988,0.02602,0.26020,5113.40734,160.95567
16.244,0.02662,0.26619,5149.45593,162.09038
16.500,0.02717,0.27172,5160.89377,162.45041
16.756,0.02781,0.27810,5187.45135,163.28637
17.012,0.02846,0.28460,5217.42445,164.22983
17.268,0.02909,0.29095,5240.44204,164.95436
17.524,0.02973,0.29729,5262.72845,165.65588
17.780,0.03021,0.30211,5283.17854,166.29959
18.036,0.03090,0.30904,5311.79439,167.20034
18.292,0.03153,0.31526,5331.38235,167.81691
18.548,0.03218,0.32176,5350.73385,168.42604
18.804,0.03277,0.32773,5374.10064,169.16156
19.060,0.03337,0.33371,5391.98809,169.72461
19.316,0.03397,0.33975,5418.34138,170.55413
19.572,0.03451,0.34509,5438.63971,171.19307
19.828,0.03515,0.35145,5461.28393,171.90585
20.084,0.03573,0.35732,5479.37666,172.47535
20.340,0.03623,0.36234,5498.25700,173.06965
20.596,0.03678,0.36783,5519.49078,173.73803
20.852,0.03738,0.37381,5544.52319,174.52598
21.108,0.03792,0.37916,5564.75422,175.16280
21.364,0.03848,0.38477,5583.95731,175.76726
21.620,0.03906,0.39056,5600.37956,176.28418
21.876,0.03962,0.39616,5628.21264,177.16029
22.132,0.04025,0.40246,5650.50311,177.86193
22.388,0.04084,0.40837,5671.72152,178.52983
22.644,0.04131,0.41314,5690.73587,179.12835
22.900,0.04184,0.41843,5708.06034,179.67367
23.156,0.04235,0.42351,5725.80748,180.23230
23.412,0.04290,0.42897,5749.43696,180.97609
23.668,0.04355,0.43551,5779.41524,181.91972
23.924,0.04410,0.44096,5792.55343,182.33328
24.180,0.04466,0.44664,5821.07701,183.23112
24.436,0.04524,0.45236,5832.60902,183.59411
24.692,0.04570,0.45696,5849.84195,184.13656
24.948,0.04637,0.46367,5880.68164,185.10730
25.204,0.04691,0.46906,5898.03822,185.65364
25.460,0.04760,0.47596,5919.94524,186.34321
25.716,0.04815,0.48145,5943.58452,187.08731
25.972,0.04869,0.48691,5962.81829,187.69273
26.228,0.04915,0.49152,5976.53718,188.12457
26.484,0.04973,0.49730,5998.15883,188.80516
26.740,0.05037,0.50367,6019.17438,189.46667
26.996,0.05087,0.50870,6031.14559,189.84349
27.252,0.05136,0.51363,6061.38540,190.79535
27.508,0.05198,0.51978,6073.73306,191.18402
27.764,0.05248,0.52480,6090.54548,191.71323
28.020,0.05306,0.53058,6113.06990,192.42223
28.276,0.05351,0.53506,6126.35434,192.84039
28.532,0.05420,0.54197,6149.62060,193.57275
28.788,0.05476,0.54757,6169.93433,194.21216
29.044,0.05517,0.55168,6183.39339,194.63582
29.300,0.05572,0.55717,6201.06447,195.19205
29.556,0.05618,0.56176,6214.49760,195.61489
29.812,0.05675,0.56751,6235.46023,196.27474
30.068,0.05724,0.57237,6263.99854,197.17304
30.324,0.05785,0.57853,6284.39884,197.81519
30.580,0.05832,0.58320,6285.29528,197.84340
30.836,0.05887,0.58868,6312.73651,198.70718
31.092,0.05950,0.59503,6337.60082,199.48983
31.348,0.06010,0.60102,6354.38255,200.01808
31.604,0.06057,0.60566,6359.77677,200.18787
31.860,0.06111,0.61113,6381.09213,200.85882
32.116,0.06172,0.61718,6409.40581,201.75005
32.372,0.06223,0.62232,6423.52600,202.19452
32.628,0.06285,0.62845,6438.77092,202.67438
32.884,0.06340,0.63399,6453.63894,203.14239
33.140,0.06403,0.64026,6467.54753,203.58019
33.396,0.06457,0.64568,6487.01229,204.19289
33.652,0.06517,0.65170,6507.88714,204.84997
33.908,0.06575,0.65751,6521.66036,205.28351
34.164,0.06625,0.66251,6533.68777,205.66210
34.420,0.06678,0.66779,6554.79110,206.32637
34.676,0.06735,0.67353,6579.33205,207.09885
34.932,0.06786,0.67858,6589.06795,207.40531
35.188,0.06838,0.68375,6601.96307,207.81121
35.444,0.06888,0.68882,6605.93568,207.93626
35.700,0.06940,0.69400,6638.14992,208.95027
35.956,0.06998,0.69977,6658.83575,209.60141
36.212,0.07047,0.70475,6676.25372,210.14967
36.468,0.07097,0.70968,6688.44233,210.53334
36.724,0.07150,0.71502,6705.23515,211.06193
36.980,0.07206,0.72060,6729.19250,211.81604
37.236,0.07258,0.72580,6740.10262,212.15946
37.492,0.07322,0.73223,6763.80318,212.90548
37.748,0.07385,0.73846,6780.43283,213.42894
38.004,0.07444,0.74445,6787.38548,213.64779
38.260,0.07489,0.74892,6805.29195,214.21143
38.516,0.07538,0.75379,6811.45177,214.40533
38.772,0.07591,0.75908,6836.95238,215.20802
39.028,0.07649,0.76486,6857.78452,215.86375
39.284,0.07696,0.76958,6866.44998,216.13652
39.540,0.07761,0.77611,6889.19940,216.85260
39.796,0.07819,0.78187,6899.98247,217.19203
40.052,0.07873,0.78733,6914.83718,217.65961
40.308,0.07928,0.79276,6931.07609,218.17076
40.564,0.07979,0.79794,6948.60263,218.72245
40.820,0.08032,0.80324,6961.45598,219.12704
41.076,0.08086,0.80863,6978.81344,219.67340
41.332,0.08147,0.81471,6995.50301,220.19874
41.588,0.08211,0.82113,7009.30323,220.63314
41.844,0.08269,0.82692,7016.20929,220.85052
42.100,0.08321,0.83213,7038.29780,221.54580
42.356,0.08384,0.83836,7061.18929,222.26636
42.612,0.08437,0.84368,7070.64272,222.56393
42.868,0.08493,0.84929,7074.72655,222.69248
43.124,0.08548,0.85479,7091.89921,223.23302
43.380,0.08609,0.86087,7111.32466,223.84448
43.636,0.08661,0.86611,7132.98276,224.52622
43.892,0.08708,0.87075,7147.80126,224.99266
44.148,0.08768,0.87676,7161.41159,225.42108
44.404,0.08826,0.88258,7170.59139,225.71003
44.660,0.08886,0.88864,7184.17542,226.13762
44.916,0.08929,0.89290,7193.55703,226.43293
45.172,0.08978,0.89785,7222.89471,227.35639
45.428,0.09028,0.90284,7235.30758,227.74712
45.684,0.09081,0.90808,7246.16448,228.08886
45.940,0.09145,0.91445,7264.02309,228.65100
46.196,0.09207,0.92074,7282.28743,229.22591
46.452,0.09263,0.92634,7298.64280,229.74073
46.708,0.09315,0.93151,7310.77661,230.12267
46.964,0.09364,0.93640,7330.36481,230.73925
47.220,0.09419,0.94189,7340.29278,231.05175
47.476,0.09479,0.94790,7351.04776,231.39029
47.732,0.09542,0.95419,7360.44165,231.68598
47.988,0.09584,0.95840,7376.41119,232.18866
48.244,0.09639,0.96390,7400.83448,232.95744
48.500,0.09683,0.96833,7406.14766,233.12468
48.756,0.09744,0.97444,7422.36409,233.63513
49.012,0.09805,0.98053,7437.70355,234.11797
49.268,0.09864,0.98636,7443.74434,234.30812
49.524,0.09901,0.99006,7455.01027,234.66274
49.780,0.09946,0.99456,7476.97404,235.35410
50.036,0.09992,0.99920,7491.48409,235.81083
50.292,0.10057,1.00570,7511.93318,236.45451
50.548,0.10108,1.01077,7506.40806,236.28060
50.804,0.10178,1.01780,7520.48306,236.72364
51.060,0.10233,1.02326,7543.98150,237.46330
51.316,0.10288,1.02875,7563.35971,238.07327
51.572,0.10337,1.03373,7575.42015,238.45290
51.828,0.10395,1.03953,7584.02693,238.72382
52.084,0.10461,1.04614,7595.41036,239.08214
52.340,0.10515,1.05152,7607.72067,239.46963
52.596,0.10568,1.05676,7626.78850,240.06983
52.852,0.10623,1.06231,7646.03444,240.67564
53.108,0.10675,1.06751,7658.76764,241.07645
53.364,0.10732,1.07325,7667.70177,241.35767
53.620,0.10788,1.07885,7670.03607,241.43114
53.876,0.10853,1.08535,7691.01041,242.09136
54.132,0.10910,1.09100,7701.96783,242.43627
54.388,0.10963,1.09634,7720.19157,243.00990
54.644,0.11013,1.10126,7730.73034,243.34163
54.900,0.11067,1.10666,7746.74835,243.84583
55.156,0.11127,1.11273,7754.63392,244.09405
55.412,0.11187,1.11868,7763.63867,244.37749
55.668,0.11246,1.12459,7790.29017,245.21641
55.924,0.11303,1.13032,7803.60685,245.63558
56.180,0.11355,1.13546,7812.70699,245.92202
56.436,0.11405,1.14046,7822.59269,246.23320
56.692,0.11455,1.14554,7842.41264,246.85707
56.948,0.11515,1.15153,7851.48336,247.14259
57.204,0.11574,1.15742,7856.00493,247.28492
57.460,0.11638,1.16378,7878.00348,247.97737
57.716,0.11687,1.16873,7888.51401,248.30822
57.972,0.11720,1.17196,7892.88892,248.44593
58.228,0.11775,1.17749,7904.61338,248.81498
58.484,0.11828,1.18279,7925.87996,249.48439
58.740,0.11887,1.18870,7940.03465,249.92994
58.996,0.11939,1.19395,7948.59229,250.19931
59.252,0.11983,1.19831,7956.31721,250.44247
59.508,0.12048,1.20478,7974.41827,251.01224
59.764,0.12104,1.21039,7987.61815,251.42773
60.020,0.12171,1.21711,8003.86670,251.93919
60.276,0.12226,1.22255,8008.17162,252.07470
60.532,0.12274,1.22742,8029.82154,252.75618
60.788,0.12331,1.23314,8044.10397,253.20575
61.044,0.12375,1.23754,8044.42802,253.21595
61.300,0.12428,1.24281,8062.06802,253.77121
61.556,0.12490,1.24899,8077.10352,254.24448
61.812,0.12559,1.25586,8093.28776,254.75392
62.068,0.12612,1.26119,8098.89578,254.93044
62.324,0.12658,1.26583,8107.44674,255.19960
62.580,0.12711,1.27113,8126.10736,255.78699
62.836,0.12777,1.27773,8133.52820,256.02057
63.092,0.12833,1.28326,8153.04548,256.63492
63.348,0.12888,1.28877,8156.74012,256.75122
63.604,0.12939,1.29390,8171.50524,257.21598
63.860,0.12991,1.29913,8182.19831,257.55257
64.116,0.13056,1.30557,8190.24006,257.80570
64.372,0.13121,1.31214,8203.97493,258.23804
64.628,0.13169,1.31694,8222.93452,258.83483
64.884,0.13222,1.32218,8230.01520,259.05771
65.140,0.13269,1.32692,8243.36445,259.47791
65.396,0.13331,1.33310,8251.10147,259.72145
65.652,0.13393,1.33926,8264.39769,260.13998
65.908,0.13449,1.34488,8272.69399,260.40112
66.164,0.13502,1.35017,8286.90953,260.84858
66.420,0.13552,1.35521,8307.01609,261.48148
66.676,0.13613,1.36129,8312.87666,261.66596
66.932,0.13669,1.36691,8322.73523,261.97628
67.188,0.13721,1.37208,8335.46191,262.37688
67.444,0.13773,1.37726,8347.64464,262.76036
67.700,0.13833,1.38328,8358.21841,263.09319
67.956,0.13904,1.39044,8372.94371,263.55670
68.212,0.13971,1.39714,8382.62847,263.86155
68.468,0.14013,1.40127,8390.11406,264.09717
68.724,0.14069,1.40695,8403.76938,264.52700
68.980,0.14127,1.41265,8421.16107,265.07445
69.236,0.14174,1.41739,8425.91862,265.22420
69.492,0.14223,1.42232,8442.86234,265.75754
69.748,0.14306,1.43064,8456.37409,266.18285
70.004,0.14352,1.43517,8460.41050,266.30991
70.260,0.14395,1.43947,8457.88882,266.23053
70.516,0.14448,1.44478,8472.14766,266.67936
70.772,0.14497,1.44969,8491.25905,267.28093
71.028,0.14549,1.45489,8498.40385,267.50583
71.284,0.14594,1.45938,8508.61730,267.82732
71.540,0.14646,1.46455,8511.44139,267.91622
71.796,0.14706,1.47059,8534.81429,268.65193
72.052,0.14762,1.47618,8549.92190,269.12747
72.308,0.14819,1.48189,8564.74251,269.59398
72.564,0.14867,1.48671,8571.85044,269.81772
72.820,0.14925,1.49253,8590.95042,270.41894
73.076,0.14972,1.49717,8587.46472,270.30922
73.332,0.15024,1.50243,8609.19113,270.99310
73.588,0.15084,1.50842,8612.62493,271.10119
73.844,0.15137,1.51371,8617.39462,271.25133
74.100,0.15193,1.51933,8631.30234,271.68910
74.356,0.15256,1.52559,8648.46118,272.22921
74.612,0.15313,1.53130,8654.68825,272.42522
74.868,0.15372,1.53722,8666.78305,272.80593
75.124,0.15418,1.54181,8670.26740,272.91561
75.380,0.15466,1.54659,8684.94634,273.37766
75.636,0.15522,1.55216,8693.89078,273.65921
75.892,0.15586,1.55857,8713.54975,274.27802
76.148,0.15638,1.56385,8710.77489,274.19067
76.404,0.15698,1.56978,8723.63428,274.59545
76.660,0.15778,1.57783,8730.43447,274.80950
76.916,0.15834,1.58343,8741.01119,275.14243
77.172,0.15883,1.58833,8760.62725,275.75989
77.428,0.15933,1.59332,8765.06155,275.89946
77.684,0.15989,1.59892,8776.19965,276.25006
77.940,0.16047,1.60469,8788.57683,276.63966
78.196,0.16103,1.61029,8796.52015,276.88969
78.452,0.16160,1.61600,8808.15603,277.25596
78.708,0.16213,1.62126,8820.04739,277.63026
78.964,0.16275,1.62746,8829.67017,277.93316
79.220,0.16329,1.63288,8839.36572,278.23835
79.476,0.16386,1.63863,8846.11207,278.45071
79.732,0.16442,1.64420,8859.81926,278.88217
79.988,0.16491,1.64907,8868.88457,279.16752
80.244,0.16546,1.65457,8882.86731,279.60766
80.500,0.16602,1.66022,8894.94400,279.98780
80.756,0.16662,1.66622,8898.22934,280.09121
81.012,0.16718,1.67181,8913.19062,280.56215
81.268,0.16779,1.67794,8919.72524,280.76784
81.524,0.16835,1.68350,8929.31782,281.06979
81.780,0.16885,1.68846,8925.35177,280.94495
82.036,0.16925,1.69249,8938.46268,281.35764
82.292,0.16985,1.69850,8956.28819,281.91874
82.548,0.17046,1.70461,8965.61933,282.21246
82.804,0.17099,1.70995,8968.26926,282.29587
83.060,0.17149,1.71492,8984.31880,282.80107
83.316,0.17194,1.71938,8998.50684,283.24767
83.572,0.17258,1.72583,9015.83312,283.79305
83.828,0.17320,1.73197,9019.56271,283.91044
84.084,0.17369,1.73693,9022.07612,283.98956
84.340,0.17431,1.74313,9034.90059,284.39324
84.596,0.17489,1.74893,9049.04007,284.83831
84.852,0.17549,1.75490,9054.39724,285.00694
85.108,0.17613,1.76133,9064.83207,285.33540
85.364,0.17665,1.76650,9071.01488,285.53001
85.620,0.17726,1.77263,9073.12129,285.59632
85.876,0.17786,1.77864,9086.06040,286.00360
86.132,0.17838,1.78384,9100.10621,286.44573
86.388,0.17894,1.78944,9106.16088,286.63631
86.644,0.17952,1.79520,9114.40917,286.89594
86.900,0.18007,1.80066,9123.17103,287.17174
87.156,0.18057,1.80571,9145.31079,287.86864
87.412,0.18114,1.81139,9144.77875,287.85189
87.668,0.18174,1.81744,9157.62255,288.25618
87.924,0.18239,1.82390,9162.01865,288.39456
88.180,0.18292,1.82925,9169.12465,288.61823
88.436,0.18350,1.83496,9180.17870,288.96618
88.692,0.18403,1.84025,9185.34630,289.12885
88.948,0.18452,1.84524,9202.25450,289.66107
89.204,0.18504,1.85037,9219.87860,290.21582
89.460,0.18570,1.85697,9223.05645,290.31585
89.716,0.18625,1.86245,9219.07983,290.19068
89.972,0.18690,1.86895,9238.91351,290.81499
90.228,0.18744,1.87441,9249.04309,291.13384
90.484,0.18792,1.87922,9256.33479,291.36336
90.740,0.18849,1.88494,9264.07836,291.60711
90.996,0.18903,1.89031,9273.43474,291.90162
91.252,0.18952,1.89522,9265.94534,291.66588
91.508,0.19007,1.90075,9281.82679,292.16578
91.764,0.19067,1.90668,9299.60605,292.72542
92.020,0.19121,1.91207,9306.49526,292.94227
92.276,0.19175,1.91746,9311.02301,293.08479
92.532,0.19223,1.92229,9307.51303,292.97431
92.788,0.19270,1.92703,9328.72005,293.64185
93.044,0.19339,1.93386,9342.59070,294.07846
93.300,0.19406,1.94063,9342.61380,294.07918
93.556,0.19465,1.94651,9362.68386,294.71093
93.812,0.19510,1.95095,9370.03646,294.94237
94.068,0.19569,1.95694,9371.93955,295.00228
94.324,0.19630,1.96300,9375.04846,295.10014
94.580,0.19689,1.96895,9394.22639,295.70380
94.836,0.19745,1.97449,9398.29818,295.83197
95.092,0.19807,1.98072,9407.55755,296.12343
95.348,0.19860,1.98599,9414.94496,296.35596
95.604,0.19919,1.99188,9429.18736,296.80428
95.860,0.19978,1.99781,9433.87642,296.95187
96.116,0.20028,2.00280,9436.24521,297.02644
96.372,0.20087,2.00866,9447.15371,297.36981
96.628,0.20147,2.01468,9460.07240,297.77645
96.884,0.20201,2.02005,9461.95998,297.83587
97.140,0.20261,2.02613,9476.49409,298.29336
97.396,0.20322,2.03218,9481.62027,298.45472
97.652,0.20368,2.03676,9487.16744,298.62933
97.908,0.20437,2.04368,9500.31482,299.04317
98.164,0.20494,2.04941,9501.52355,299.08121
98.420,0.20545,2.05454,9514.40976,299.48684
98.676,0.20602,2.06024,9520.68298,299.68430
98.932,0.20659,2.06587,9531.41122,300.02199
99.188,0.20718,2.07177,9536.71814,300.18904
99.444,0.20768,2.07682,9533.96784,300.10247
99.700,0.20812,2.08118,9520.54322,299.67990
99.956,0.20847,2.08467,9519.95861,299.66150
100.212,0.20892,2.08919,9543.91013,300.41543
100.468,0.20945,2.09450,9562.64025,301.00500
100.724,0.21006,2.10058,9585.54961,301.72612
100.980,0.21066,2.10657,9592.06968,301.93135
101.236,0.21119,2.11187,9601.47383,302.22737
101.492,0.21174,2.11739,9605.52225,302.35480
101.748,0.21242,2.12416,9610.64358,302.51601
102.004,0.21288,2.12878,9626.03142,303.00037
102.260,0.21346,2.13464,9632.63685,303.20829
102.516,0.21401,2.14013,9645.75100,303.62109
102.772,0.21460,2.14603,9638.62152,303.39667
103.028,0.21525,2.15249,9655.81714,303.93794
103.284,0.21581,2.15811,9667.68401,304.31148
103.540,0.21636,2.16360,9669.48623,304.36821
103.796,0.21695,2.16950,9683.02236,304.79429
104.052,0.21751,2.17509,9678.55577,304.65369
104.308,0.21805,2.18051,9684.00507,304.82522
104.564,0.21861,2.18614,9689.82926,305.00855
104.820,0.21919,2.19195,9697.90940,305.26289
105.076,0.21972,2.19716,9706.73185,305.54059
105.332,0.22033,2.20329,9709.30391,305.62156
105.588,0.22080,2.20798,9707.67221,305.57019
105.844,0.22132,2.21320,9722.95519,306.05126
106.100,0.22191,2.21910,9736.64009,306.48202
106.356,0.22242,2.22419,9740.51162,306.60389
106.612,0.22297,2.22971,9745.63143,306.76504
106.868,0.22350,2.23502,9753.53571,307.01385
107.124,0.22407,2.24071,9753.42834,307.01047
107.380,0.22460,2.24596,9767.72789,307.46058
107.636,0.22507,2.25070,9777.52518,307.76897
107.892,0.22573,2.25728,9783.77645,307.96574
108.148,0.22628,2.26277,9794.67756,308.30888
108.404,0.22685,2.26845,9798.95397,308.44349
108.660,0.22731,2.27307,9805.96231,308.66409
108.916,0.22795,2.27953,9815.12565,308.95253
109.172,0.22853,2.28534,9821.39910,309.15000
109.428,0.22913,2.29125,9830.11210,309.42426
109.684,0.22973,2.29731,9832.64543,309.50400
109.940,0.23039,2.30392,9835.26600,309.58649
110.196,0.23100,2.30999,9845.27794,309.90164
110.452,0.23151,2.31511,9855.42069,310.22090
110.708,0.23211,2.32111,9865.25813,310.53056
110.964,0.23263,2.32628,9868.48529,310.63214
111.220,0.23318,2.33184,9873.82332,310.80016
111.476,0.23382,2.33818,9883.39726,311.10152
111.732,0.23446,2.34460,9892.66484,311.39324
111.988,0.23504,2.35042,9900.66177,311.64496
112.244,0.23544,2.35440,9901.90261,311.68402
112.500,0.23608,2.36080,9912.32650,312.01214
112.756,0.23662,2.36622,9918.97688,312.22147
113.012,0.23718,2.37177,9921.86224,312.31229
113.268,0.23775,2.37753,9926.38780,312.45475
113.524,0.23820,2.38203,9932.86339,312.65858
113.780,0.23884,2.38836,9936.72987,312.78028
114.036,0.23938,2.39377,9954.73591,313.34706
114.292,0.23993,2.39928,9961.82583,313.57024
114.548,0.24057,2.40569,9958.13398,313.45403
114.804,0.24105,2.41049,9974.60377,313.97245
115.060,0.24161,2.41615,9981.45866,314.18822
115.316,0.24222,2.42218,9990.79616,314.48214
115.572,0.24281,2.42812,9995.28433,314.62341
115.828,0.24346,2.43456,9999.37433,314.75216
116.084,0.24401,2.44009,10002.10249,314.83803
116.340,0.24454,2.44542,10006.25749,314.96882
116.596,0.24510,2.45100,10008.70088,315.04573
116.852,0.24565,2.45649,10022.19551,315.47050
117.108,0.24619,2.46189,10031.66962,315.76872
117.364,0.24681,2.46809,10032.11248,315.78266
117.620,0.24745,2.47452,10038.50417,315.98385
117.876,0.24802,2.48023,10048.10718,316.28613
118.132,0.24865,2.48645,10056.34289,316.54537
118.388,0.24931,2.49311,10057.94253,316.59572
118.644,0.24981,2.49810,10065.17352,316.82333
118.900,0.25040,2.50397,10063.64282,316.77515
119.156,0.25098,2.50982,10072.50763,317.05419
119.412,0.25158,2.51578,10076.90745,317.19268
119.668,0.25215,2.52148,10092.45339,317.68202
119.924,0.25278,2.52785,10097.36837,317.83673
120.180,0.25325,2.53245,10094.04210,317.73203
120.436,0.25387,2.53872,10101.01936,317.95166
120.692,0.25449,2.54491,10117.90291,318.48310
120.948,0.25510,2.55103,10126.14131,318.74242
121.204,0.25554,2.55544,10127.23412,318.77682
121.460,0.25618,2.56184,10138.34771,319.12665
121.716,0.25671,2.56711,10137.72212,319.10696
121.972,0.25733,2.57329,10141.05163,319.21176
122.228,0.25793,2.57934,10146.98094,319.39840
122.484,0.25853,2.58527,10164.46947,319.94889
122.740,0.25918,2.59182,10169.43093,320.10506
122.996,0.25974,2.59741,10167.40416,320.04126
123.252,0.26028,2.60284,10176.93121,320.34115
123.508,0.26080,2.60797,10185.18527,320.60096
123.764,0.26152,2.61516,10191.17327,320.78945
124.020,0.26214,2.62137,10202.11140,321.13375
124.276,0.26271,2.62709,10207.18083,321.29332
124.532,0.26326,2.63256,10205.64278,321.24491
124.788,0.26381,2.63810,10207.47507,321.30258
125.044,0.26437,2.64375,10218.32568,321.64413
125.300,0.26498,2.64980,10222.27262,321.76837
125.556,0.26547,2.65469,10225.36227,321.86562
125.812,0.26609,2.66090,10231.64779,322.06347
126.068,0.26667,2.66670,10239.40371,322.30761
126.324,0.26744,2.67439,10246.16670,322.52049
126.580,0.26799,2.67992,10251.04771,322.67413
126.836,0.26858,2.68580,10253.20062,322.74189
127.092,0.26919,2.69194,10259.79015,322.94931
127.348,0.26969,2.69695,10270.36049,323.28204
127.604,0.27022,2.70220,10264.79947,323.10699
127.860,0.27080,2.70796,10268.26805,323.21617
128.116,0.27129,2.71289,10268.97987,323.23858
128.372,0.27184,2.71835,10285.01460,323.74331
128.628,0.27242,2.72422,10289.27346,323.87736
128.884,0.27297,2.72967,10299.66611,324.20450
129.140,0.27359,2.73589,10303.51267,324.32558
129.396,0.27401,2.74009,10297.27058,324.12909
129.652,0.27454,2.74539,10297.62259,324.14017
129.908,0.27508,2.75077,10299.15066,324.18827
130.164,0.27559,2.75589,10331.84541,325.21741
130.420,0.27621,2.76209,10335.15133,325.32147
130.676,0.27676,2.76762,10340.34193,325.48486
130.932,0.27726,2.77264,10337.75060,325.40329
131.188,0.27784,2.77844,10345.45055,325.64566
131.444,0.27834,2.78341,10352.06074,325.85373
131.700,0.27884,2.78843,10361.39090,326.14742
131.956,0.27942,2.79419,10368.28582,326.36445
132.212,0.27998,2.79983,10379.48389,326.71694
132.468,0.28059,2.80588,10384.55440,326.87654
132.724,0.28118,2.81183,10389.84359,327.04303
132.980,0.28177,2.81767,10387.03113,326.95450
133.236,0.28227,2.82274,10396.25554,327.24486
133.492,0.28284,2.82839,10395.37760,327.21722
133.748,0.28329,2.83292,10398.20929,327.30636
134.004,0.28377,2.83767,10403.58650,327.47562
134.260,0.28449,2.84488,10417.46263,327.91240
134.516,0.28488,2.84878,10410.79919,327.70265
134.772,0.28551,2.85511,10413.60895,327.79110
135.028,0.28609,2.86094,10413.81738,327.79766
135.284,0.28664,2.86637,10429.15026,328.28029
135.540,0.28720,2.87204,10440.39531,328.63426
135.796,0.28770,2.87700,10442.52170,328.70119
136.052,0.28825,2.88252,10441.78952,328.67814
136.308,0.28876,2.88765,10449.29126,328.91427
136.564,0.28918,2.89185,10449.64101,328.92528
136.820,0.28976,2.89765,10454.60831,329.08164
137.076,0.22084,2.20836,1762.90574,55.49131